2024-11-04 17:28:51.148 | INFO     | __main__:serve:67 - 启动服务：192.168.0.102:8936
2024-11-04 17:28:51.164 | INFO     | __main__:serve:69 - 服务注册开始
2024-11-04 17:28:51.169 | INFO     | common.register.consul:register_grpc:61 - http://192.168.0.102:8936/health
2024-11-04 17:28:51.169 | INFO     | common.register.consul:register_grpc:63 - HTTP健康检查服务注册成功
2024-11-04 17:37:00.709 | ERROR    | grpc._server:_call_behavior:610 - An error has been caught in function '_call_behavior', process 'MainProcess' (5048), thread 'ThreadPoolExecutor-0_0' (21568):
Traceback (most recent call last):

  File "D:\Miniconda3\Lib\threading.py", line 1030, in _bootstrap
    self._bootstrap_inner()
    │    └ <function Thread._bootstrap_inner at 0x0000021E673F19E0>
    └ <Thread(ThreadPoolExecutor-0_0, started daemon 21568)>
  File "D:\Miniconda3\Lib\threading.py", line 1073, in _bootstrap_inner
    self.run()
    │    └ <function Thread.run at 0x0000021E673F16C0>
    └ <Thread(ThreadPoolExecutor-0_0, started daemon 21568)>
  File "D:\Miniconda3\Lib\threading.py", line 1010, in run
    self._target(*self._args, **self._kwargs)
    │    │        │    │        │    └ {}
    │    │        │    │        └ <Thread(ThreadPoolExecutor-0_0, started daemon 21568)>
    │    │        │    └ (<weakref at 0x0000021E6AAEC860; to 'ThreadPoolExecutor' at 0x0000021E6A40E5A0>, <_queue.SimpleQueue object at 0x0000021E6A8E...
    │    │        └ <Thread(ThreadPoolExecutor-0_0, started daemon 21568)>
    │    └ <function _worker at 0x0000021E6A90F2E0>
    └ <Thread(ThreadPoolExecutor-0_0, started daemon 21568)>
  File "D:\Miniconda3\Lib\concurrent\futures\thread.py", line 92, in _worker
    work_item.run()
    │         └ <function _WorkItem.run at 0x0000021E6A90F420>
    └ <concurrent.futures.thread._WorkItem object at 0x0000021E6AB08F20>
  File "D:\Miniconda3\Lib\concurrent\futures\thread.py", line 58, in run
    result = self.fn(*self.args, **self.kwargs)
             │    │   │    │       │    └ {}
             │    │   │    │       └ <concurrent.futures.thread._WorkItem object at 0x0000021E6AB08F20>
             │    │   │    └ (<function _unary_response_in_pool at 0x0000021E6AAD6980>, <grpc._cython.cygrpc.RequestCallEvent object at 0x0000021E6AAED120...
             │    │   └ <concurrent.futures.thread._WorkItem object at 0x0000021E6AB08F20>
             │    └ <built-in method run of _contextvars.Context object at 0x0000021E6A8A6D40>
             └ <concurrent.futures.thread._WorkItem object at 0x0000021E6AB08F20>
  File "E:\workspace\Mall_srv\venv\Lib\site-packages\grpc\_server.py", line 793, in _unary_response_in_pool
    response, proceed = _call_behavior(
                        └ <function _call_behavior at 0x0000021E6AAD6520>
> File "E:\workspace\Mall_srv\venv\Lib\site-packages\grpc\_server.py", line 610, in _call_behavior
    response_or_iterator = behavior(argument, context)
                           │        │         └ <grpc._server._Context object at 0x0000021E6AB0A690>
                           │        └ 
                           └ <bound method UserFavServicer.GetFavList of <userop_srv.handler.userfav.userfav.UserFavServicer object at 0x0000021E6A919700>>

  File "E:\workspace\Mall_srv\userop_srv\handler\userfav\userfav.py", line 18, in GetFavList
    if request.goodsId:
       └

AttributeError: goodsId
2024-11-04 17:39:39.250 | INFO     | __main__:on_exit:27 - 注销<frame at 0x0000021E6AAC5C40, file 'D:\\Miniconda3\\Lib\\threading.py', line 359, code wait>服务
2024-11-04 17:39:39.254 | ERROR    | common.register.consul:unregister:75 - 注销失败:404
2024-11-04 17:39:39.254 | INFO     | __main__:on_exit:29 - 注销成功
