2024-11-04 17:27:49.464 | INFO     | __main__:serve:67 - 启动服务：192.168.0.102:8737
2024-11-04 17:27:49.468 | INFO     | __main__:serve:69 - 服务注册开始
2024-11-04 17:27:49.473 | INFO     | common.register.consul:register_grpc:61 - http://192.168.0.102:8737/health
2024-11-04 17:27:49.473 | INFO     | common.register.consul:register_grpc:63 - HTTP健康检查服务注册成功
2024-11-04 17:28:19.380 | ERROR    | grpc._server:_call_behavior:610 - An error has been caught in function '_call_behavior', process 'MainProcess' (14620), thread 'ThreadPoolExecutor-0_0' (25772):
Traceback (most recent call last):

  File "D:\Miniconda3\Lib\threading.py", line 1030, in _bootstrap
    self._bootstrap_inner()
    │    └ <function Thread._bootstrap_inner at 0x000001C2506319E0>
    └ <Thread(ThreadPoolExecutor-0_0, started daemon 25772)>
  File "D:\Miniconda3\Lib\threading.py", line 1073, in _bootstrap_inner
    self.run()
    │    └ <function Thread.run at 0x000001C2506316C0>
    └ <Thread(ThreadPoolExecutor-0_0, started daemon 25772)>
  File "D:\Miniconda3\Lib\threading.py", line 1010, in run
    self._target(*self._args, **self._kwargs)
    │    │        │    │        │    └ {}
    │    │        │    │        └ <Thread(ThreadPoolExecutor-0_0, started daemon 25772)>
    │    │        │    └ (<weakref at 0x000001C253E0C860; to 'ThreadPoolExecutor' at 0x000001C253A0B0B0>, <_queue.SimpleQueue object at 0x000001C253BA...
    │    │        └ <Thread(ThreadPoolExecutor-0_0, started daemon 25772)>
    │    └ <function _worker at 0x000001C253BCF380>
    └ <Thread(ThreadPoolExecutor-0_0, started daemon 25772)>
  File "D:\Miniconda3\Lib\concurrent\futures\thread.py", line 92, in _worker
    work_item.run()
    │         └ <function _WorkItem.run at 0x000001C253BCF4C0>
    └ <concurrent.futures.thread._WorkItem object at 0x000001C253DEB950>
  File "D:\Miniconda3\Lib\concurrent\futures\thread.py", line 58, in run
    result = self.fn(*self.args, **self.kwargs)
             │    │   │    │       │    └ {}
             │    │   │    │       └ <concurrent.futures.thread._WorkItem object at 0x000001C253DEB950>
             │    │   │    └ (<function _unary_response_in_pool at 0x000001C253DF6980>, <grpc._cython.cygrpc.RequestCallEvent object at 0x000001C253767F60...
             │    │   └ <concurrent.futures.thread._WorkItem object at 0x000001C253DEB950>
             │    └ <built-in method run of _contextvars.Context object at 0x000001C253DFF0C0>
             └ <concurrent.futures.thread._WorkItem object at 0x000001C253DEB950>
  File "E:\workspace\Mall_srv\venv\Lib\site-packages\grpc\_server.py", line 793, in _unary_response_in_pool
    response, proceed = _call_behavior(
                        └ <function _call_behavior at 0x000001C253DF6520>
> File "E:\workspace\Mall_srv\venv\Lib\site-packages\grpc\_server.py", line 610, in _call_behavior
    response_or_iterator = behavior(argument, context)
                           │        │         └ <grpc._server._Context object at 0x000001C253DEB9E0>
                           │        └ 
                           └ <bound method MessageServicer.MessageList of <userop_srv.handler.message.message.MessageServicer object at 0x000001C253DEA270>>

  File "E:\workspace\Mall_srv\userop_srv\handler\message\message.py", line 18, in MessageList
    message_rsp.userId = message.user_id
    │                    └ <LeavingMessages: 1>
    └ id: 1

AttributeError: 'LeavingMessages' object has no attribute 'user_id'
2024-11-04 17:28:49.713 | INFO     | __main__:on_exit:27 - 注销<frame at 0x000001C253DE7760, file 'D:\\Miniconda3\\Lib\\threading.py', line 359, code wait>服务
2024-11-04 17:28:49.717 | ERROR    | common.register.consul:unregister:75 - 注销失败:404
2024-11-04 17:28:49.717 | INFO     | __main__:on_exit:29 - 注销成功
