2024-11-04 17:48:38.128 | INFO     | __main__:serve:67 - 启动服务：192.168.0.102:12365
2024-11-04 17:48:38.142 | INFO     | __main__:serve:69 - 服务注册开始
2024-11-04 17:48:38.153 | INFO     | common.register.consul:register_grpc:61 - http://192.168.0.102:12365/health
2024-11-04 17:48:38.153 | INFO     | common.register.consul:register_grpc:63 - HTTP健康检查服务注册成功
2024-11-04 17:53:38.313 | ERROR    | grpc._server:_call_behavior:610 - An error has been caught in function '_call_behavior', process 'MainProcess' (21132), thread 'ThreadPoolExecutor-0_0' (23872):
Traceback (most recent call last):

  File "D:\Miniconda3\Lib\threading.py", line 1030, in _bootstrap
    self._bootstrap_inner()
    │    └ <function Thread._bootstrap_inner at 0x000001E986122980>
    └ <Thread(ThreadPoolExecutor-0_0, started daemon 23872)>
  File "D:\Miniconda3\Lib\threading.py", line 1073, in _bootstrap_inner
    self.run()
    │    └ <function Thread.run at 0x000001E986122660>
    └ <Thread(ThreadPoolExecutor-0_0, started daemon 23872)>
  File "D:\Miniconda3\Lib\threading.py", line 1010, in run
    self._target(*self._args, **self._kwargs)
    │    │        │    │        │    └ {}
    │    │        │    │        └ <Thread(ThreadPoolExecutor-0_0, started daemon 23872)>
    │    │        │    └ (<weakref at 0x000001E98AD27F10; to 'ThreadPoolExecutor' at 0x000001E98A8297C0>, <_queue.SimpleQueue object at 0x000001E98AAD...
    │    │        └ <Thread(ThreadPoolExecutor-0_0, started daemon 23872)>
    │    └ <function _worker at 0x000001E98AAC7EC0>
    └ <Thread(ThreadPoolExecutor-0_0, started daemon 23872)>
  File "D:\Miniconda3\Lib\concurrent\futures\thread.py", line 92, in _worker
    work_item.run()
    │         └ <function _WorkItem.run at 0x000001E98AADC0E0>
    └ <concurrent.futures.thread._WorkItem object at 0x000001E98B4538C0>
  File "D:\Miniconda3\Lib\concurrent\futures\thread.py", line 58, in run
    result = self.fn(*self.args, **self.kwargs)
             │    │   │    │       │    └ {}
             │    │   │    │       └ <concurrent.futures.thread._WorkItem object at 0x000001E98B4538C0>
             │    │   │    └ (<function _unary_response_in_pool at 0x000001E98AB134C0>, <grpc._cython.cygrpc.RequestCallEvent object at 0x000001E98AD29350...
             │    │   └ <concurrent.futures.thread._WorkItem object at 0x000001E98B4538C0>
             │    └ <built-in method run of _contextvars.Context object at 0x000001E98AB16C40>
             └ <concurrent.futures.thread._WorkItem object at 0x000001E98B4538C0>
  File "E:\workspace\Mall_srv\venv\Lib\site-packages\grpc\_server.py", line 793, in _unary_response_in_pool
    response, proceed = _call_behavior(
                        └ <function _call_behavior at 0x000001E98AB12C00>
> File "E:\workspace\Mall_srv\venv\Lib\site-packages\grpc\_server.py", line 610, in _call_behavior
    response_or_iterator = behavior(argument, context)
                           │        │         └ <grpc._server._Context object at 0x000001E98B453860>
                           │        └ userId: 1
                           │          goods: 421
                           │          
                           └ <bound method UserFavServicer.AddUserFav of <userop_srv.handler.userfav.userfav.UserFavServicer object at 0x000001E98AAF28A0>>

  File "E:\workspace\Mall_srv\userop_srv\handler\userfav\userfav.py", line 44, in AddUserFav
    userfav.goods = request.goodsId
    │       │       └ userId: 1
    │       │         goods: 421
    │       │         
    │       └ <peewee.FieldAccessor object at 0x000001E989586750>
    └ <UserFav: (1, None)>

AttributeError: goodsId
2024-11-04 17:54:13.419 | INFO     | __main__:on_exit:27 - 注销<frame at 0x000001E98AAA8040, file 'D:\\Miniconda3\\Lib\\threading.py', line 359, code wait>服务
2024-11-04 17:54:13.426 | ERROR    | common.register.consul:unregister:75 - 注销失败:404
2024-11-04 17:54:13.426 | INFO     | __main__:on_exit:29 - 注销成功
