2024-11-04 17:39:40.701 | INFO     | __main__:serve:67 - 启动服务：192.168.0.102:10750
2024-11-04 17:39:40.704 | INFO     | __main__:serve:69 - 服务注册开始
2024-11-04 17:39:40.709 | INFO     | common.register.consul:register_grpc:61 - http://192.168.0.102:10750/health
2024-11-04 17:39:40.709 | INFO     | common.register.consul:register_grpc:63 - HTTP健康检查服务注册成功
2024-11-04 17:39:48.110 | ERROR    | grpc._server:_call_behavior:610 - An error has been caught in function '_call_behavior', process 'MainProcess' (4888), thread 'ThreadPoolExecutor-0_0' (10852):
Traceback (most recent call last):

  File "D:\Miniconda3\Lib\threading.py", line 1030, in _bootstrap
    self._bootstrap_inner()
    │    └ <function Thread._bootstrap_inner at 0x000002D1A84019E0>
    └ <Thread(ThreadPoolExecutor-0_0, started daemon 10852)>
  File "D:\Miniconda3\Lib\threading.py", line 1073, in _bootstrap_inner
    self.run()
    │    └ <function Thread.run at 0x000002D1A84016C0>
    └ <Thread(ThreadPoolExecutor-0_0, started daemon 10852)>
  File "D:\Miniconda3\Lib\threading.py", line 1010, in run
    self._target(*self._args, **self._kwargs)
    │    │        │    │        │    └ {}
    │    │        │    │        └ <Thread(ThreadPoolExecutor-0_0, started daemon 10852)>
    │    │        │    └ (<weakref at 0x000002D1ABAE0860; to 'ThreadPoolExecutor' at 0x000002D1AB2267E0>, <_queue.SimpleQueue object at 0x000002D1AB8F...
    │    │        └ <Thread(ThreadPoolExecutor-0_0, started daemon 10852)>
    │    └ <function _worker at 0x000002D1AB91F240>
    └ <Thread(ThreadPoolExecutor-0_0, started daemon 10852)>
  File "D:\Miniconda3\Lib\concurrent\futures\thread.py", line 92, in _worker
    work_item.run()
    │         └ <function _WorkItem.run at 0x000002D1AB91F380>
    └ <concurrent.futures.thread._WorkItem object at 0x000002D1ABABE810>
  File "D:\Miniconda3\Lib\concurrent\futures\thread.py", line 58, in run
    result = self.fn(*self.args, **self.kwargs)
             │    │   │    │       │    └ {}
             │    │   │    │       └ <concurrent.futures.thread._WorkItem object at 0x000002D1ABABE810>
             │    │   │    └ (<function _unary_response_in_pool at 0x000002D1ABACA8E0>, <grpc._cython.cygrpc.RequestCallEvent object at 0x000002D1AB205350...
             │    │   └ <concurrent.futures.thread._WorkItem object at 0x000002D1ABABE810>
             │    └ <built-in method run of _contextvars.Context object at 0x000002D1ABAA2A00>
             └ <concurrent.futures.thread._WorkItem object at 0x000002D1ABABE810>
  File "E:\workspace\Mall_srv\venv\Lib\site-packages\grpc\_server.py", line 793, in _unary_response_in_pool
    response, proceed = _call_behavior(
                        └ <function _call_behavior at 0x000002D1ABACA480>
> File "E:\workspace\Mall_srv\venv\Lib\site-packages\grpc\_server.py", line 610, in _call_behavior
    response_or_iterator = behavior(argument, context)
                           │        │         └ <grpc._server._Context object at 0x000002D1ABABEF00>
                           │        └ 
                           └ <bound method UserFavServicer.GetFavList of <userop_srv.handler.userfav.userfav.UserFavServicer object at 0x000002D1ABABDF40>>

  File "E:\workspace\Mall_srv\userop_srv\handler\userfav\userfav.py", line 24, in GetFavList
    if request.goodsId:
       └

AttributeError: goodsId
2024-11-04 17:41:36.943 | INFO     | __main__:on_exit:27 - 注销<frame at 0x000002D1ABABBAE0, file 'D:\\Miniconda3\\Lib\\threading.py', line 359, code wait>服务
2024-11-04 17:41:36.951 | ERROR    | common.register.consul:unregister:75 - 注销失败:404
2024-11-04 17:41:36.951 | INFO     | __main__:on_exit:29 - 注销成功
