2024-11-04 17:54:15.698 | INFO     | __main__:serve:67 - 启动服务：192.168.0.102:13802
2024-11-04 17:54:15.704 | INFO     | __main__:serve:69 - 服务注册开始
2024-11-04 17:54:15.710 | INFO     | common.register.consul:register_grpc:61 - http://192.168.0.102:13802/health
2024-11-04 17:54:15.710 | INFO     | common.register.consul:register_grpc:63 - HTTP健康检查服务注册成功
2024-11-04 17:54:21.303 | ERROR    | grpc._server:_call_behavior:610 - An error has been caught in function '_call_behavior', process 'MainProcess' (22220), thread 'ThreadPoolExecutor-0_0' (6560):
Traceback (most recent call last):

  File "D:\Miniconda3\Lib\threading.py", line 1030, in _bootstrap
    self._bootstrap_inner()
    │    └ <function Thread._bootstrap_inner at 0x0000018903AA19E0>
    └ <Thread(ThreadPoolExecutor-0_0, started daemon 6560)>
  File "D:\Miniconda3\Lib\threading.py", line 1073, in _bootstrap_inner
    self.run()
    │    └ <function Thread.run at 0x0000018903AA16C0>
    └ <Thread(ThreadPoolExecutor-0_0, started daemon 6560)>
  File "D:\Miniconda3\Lib\threading.py", line 1010, in run
    self._target(*self._args, **self._kwargs)
    │    │        │    │        │    └ {}
    │    │        │    │        └ <Thread(ThreadPoolExecutor-0_0, started daemon 6560)>
    │    │        │    └ (<weakref at 0x000001890719C810; to 'ThreadPoolExecutor' at 0x0000018906BCB320>, <_queue.SimpleQueue object at 0x0000018906FD...
    │    │        └ <Thread(ThreadPoolExecutor-0_0, started daemon 6560)>
    │    └ <function _worker at 0x0000018906FFF240>
    └ <Thread(ThreadPoolExecutor-0_0, started daemon 6560)>
  File "D:\Miniconda3\Lib\concurrent\futures\thread.py", line 92, in _worker
    work_item.run()
    │         └ <function _WorkItem.run at 0x0000018906FFF380>
    └ <concurrent.futures.thread._WorkItem object at 0x000001890717A630>
  File "D:\Miniconda3\Lib\concurrent\futures\thread.py", line 58, in run
    result = self.fn(*self.args, **self.kwargs)
             │    │   │    │       │    └ {}
             │    │   │    │       └ <concurrent.futures.thread._WorkItem object at 0x000001890717A630>
             │    │   │    └ (<function _unary_response_in_pool at 0x00000189071868E0>, <grpc._cython.cygrpc.RequestCallEvent object at 0x00000189068E52B0...
             │    │   └ <concurrent.futures.thread._WorkItem object at 0x000001890717A630>
             │    └ <built-in method run of _contextvars.Context object at 0x0000018906FFB900>
             └ <concurrent.futures.thread._WorkItem object at 0x000001890717A630>
  File "E:\workspace\Mall_srv\venv\Lib\site-packages\grpc\_server.py", line 793, in _unary_response_in_pool
    response, proceed = _call_behavior(
                        └ <function _call_behavior at 0x0000018907186480>
> File "E:\workspace\Mall_srv\venv\Lib\site-packages\grpc\_server.py", line 610, in _call_behavior
    response_or_iterator = behavior(argument, context)
                           │        │         └ <grpc._server._Context object at 0x000001890717B140>
                           │        └ userId: 1
                           │          goods: 421
                           │          
                           └ <bound method UserFavServicer.AddUserFav of <userop_srv.handler.userfav.userfav.UserFavServicer object at 0x0000018907179EB0>>

  File "E:\workspace\Mall_srv\userop_srv\handler\userfav\userfav.py", line 44, in AddUserFav
    userfav.goods = request.goodsId
    │       │       └ userId: 1
    │       │         goods: 421
    │       │         
    │       └ <peewee.FieldAccessor object at 0x00000189068DA960>
    └ <UserFav: (1, None)>

AttributeError: goodsId
2024-11-04 17:54:37.153 | INFO     | __main__:on_exit:27 - 注销<frame at 0x0000018907176B20, file 'D:\\Miniconda3\\Lib\\threading.py', line 359, code wait>服务
2024-11-04 17:54:37.159 | ERROR    | common.register.consul:unregister:75 - 注销失败:404
2024-11-04 17:54:37.159 | INFO     | __main__:on_exit:29 - 注销成功
