2024-11-04 18:15:57.488 | INFO     | __main__:serve:67 - 启动服务：192.168.0.102:4563
2024-11-04 18:15:57.500 | INFO     | __main__:serve:69 - 服务注册开始
2024-11-04 18:15:57.504 | INFO     | common.register.consul:register_grpc:61 - http://192.168.0.102:4563/health
2024-11-04 18:15:57.504 | INFO     | common.register.consul:register_grpc:63 - HTTP健康检查服务注册成功
2024-11-04 18:16:03.237 | ERROR    | grpc._server:_call_behavior:610 - An error has been caught in function '_call_behavior', process 'MainProcess' (20608), thread 'ThreadPoolExecutor-0_0' (10816):
Traceback (most recent call last):

  File "D:\Miniconda3\Lib\threading.py", line 1030, in _bootstrap
    self._bootstrap_inner()
    │    └ <function Thread._bootstrap_inner at 0x000001A1FBA919E0>
    └ <Thread(ThreadPoolExecutor-0_0, started daemon 10816)>
  File "D:\Miniconda3\Lib\threading.py", line 1073, in _bootstrap_inner
    self.run()
    │    └ <function Thread.run at 0x000001A1FBA916C0>
    └ <Thread(ThreadPoolExecutor-0_0, started daemon 10816)>
  File "D:\Miniconda3\Lib\threading.py", line 1010, in run
    self._target(*self._args, **self._kwargs)
    │    │        │    │        │    └ {}
    │    │        │    │        └ <Thread(ThreadPoolExecutor-0_0, started daemon 10816)>
    │    │        │    └ (<weakref at 0x000001A1FF1B0810; to 'ThreadPoolExecutor' at 0x000001A1FE9267E0>, <_queue.SimpleQueue object at 0x000001A1FEFF...
    │    │        └ <Thread(ThreadPoolExecutor-0_0, started daemon 10816)>
    │    └ <function _worker at 0x000001A1FF01F240>
    └ <Thread(ThreadPoolExecutor-0_0, started daemon 10816)>
  File "D:\Miniconda3\Lib\concurrent\futures\thread.py", line 92, in _worker
    work_item.run()
    │         └ <function _WorkItem.run at 0x000001A1FF01F380>
    └ <concurrent.futures.thread._WorkItem object at 0x000001A1FF18E210>
  File "D:\Miniconda3\Lib\concurrent\futures\thread.py", line 58, in run
    result = self.fn(*self.args, **self.kwargs)
             │    │   │    │       │    └ {}
             │    │   │    │       └ <concurrent.futures.thread._WorkItem object at 0x000001A1FF18E210>
             │    │   │    └ (<function _unary_response_in_pool at 0x000001A1FF19A840>, <grpc._cython.cygrpc.RequestCallEvent object at 0x000001A1FF1976A0...
             │    │   └ <concurrent.futures.thread._WorkItem object at 0x000001A1FF18E210>
             │    └ <built-in method run of _contextvars.Context object at 0x000001A1FF1A3900>
             └ <concurrent.futures.thread._WorkItem object at 0x000001A1FF18E210>
  File "E:\workspace\Mall_srv\venv\Lib\site-packages\grpc\_server.py", line 793, in _unary_response_in_pool
    response, proceed = _call_behavior(
                        └ <function _call_behavior at 0x000001A1FF19A3E0>
> File "E:\workspace\Mall_srv\venv\Lib\site-packages\grpc\_server.py", line 610, in _call_behavior
    response_or_iterator = behavior(argument, context)
                           │        │         └ <grpc._server._Context object at 0x000001A1FF18E780>
                           │        └ userId: 1
                           │          
                           └ <bound method UserFavServicer.GetFavList of <userop_srv.handler.userfav.userfav.UserFavServicer object at 0x000001A1FF18DEB0>>

  File "E:\workspace\Mall_srv\userop_srv\handler\userfav\userfav.py", line 35, in GetFavList
    fav_rsp.goodsId = fav.goods
    │                 │   └ <peewee.FieldAccessor object at 0x000001A1FE8FA960>
    │                 └ <UserFav: (1, 421)>
    └ userId: 1

AttributeError: Protocol message UserFavResponse has no "goodsId" field.
2024-11-04 18:16:27.753 | INFO     | __main__:on_exit:27 - 注销<frame at 0x000001A1FF18AC00, file 'D:\\Miniconda3\\Lib\\threading.py', line 359, code wait>服务
2024-11-04 18:16:27.757 | ERROR    | common.register.consul:unregister:75 - 注销失败:404
2024-11-04 18:16:27.757 | INFO     | __main__:on_exit:29 - 注销成功
