2024-11-04 18:14:55.132 | INFO     | __main__:serve:67 - 启动服务：192.168.0.102:4363
2024-11-04 18:14:55.149 | INFO     | __main__:serve:69 - 服务注册开始
2024-11-04 18:14:55.155 | INFO     | common.register.consul:register_grpc:61 - http://192.168.0.102:4363/health
2024-11-04 18:14:55.155 | INFO     | common.register.consul:register_grpc:63 - HTTP健康检查服务注册成功
2024-11-04 18:15:08.899 | ERROR    | grpc._server:_call_behavior:610 - An error has been caught in function '_call_behavior', process 'MainProcess' (27116), thread 'ThreadPoolExecutor-0_0' (6872):
Traceback (most recent call last):

  File "D:\Miniconda3\Lib\threading.py", line 1030, in _bootstrap
    self._bootstrap_inner()
    │    └ <function Thread._bootstrap_inner at 0x0000010F1FC619E0>
    └ <Thread(ThreadPoolExecutor-0_0, started daemon 6872)>
  File "D:\Miniconda3\Lib\threading.py", line 1073, in _bootstrap_inner
    self.run()
    │    └ <function Thread.run at 0x0000010F1FC616C0>
    └ <Thread(ThreadPoolExecutor-0_0, started daemon 6872)>
  File "D:\Miniconda3\Lib\threading.py", line 1010, in run
    self._target(*self._args, **self._kwargs)
    │    │        │    │        │    └ {}
    │    │        │    │        └ <Thread(ThreadPoolExecutor-0_0, started daemon 6872)>
    │    │        │    └ (<weakref at 0x0000010F233707C0; to 'ThreadPoolExecutor' at 0x0000010F22D7B320>, <_queue.SimpleQueue object at 0x0000010F2318...
    │    │        └ <Thread(ThreadPoolExecutor-0_0, started daemon 6872)>
    │    └ <function _worker at 0x0000010F231AF1A0>
    └ <Thread(ThreadPoolExecutor-0_0, started daemon 6872)>
  File "D:\Miniconda3\Lib\concurrent\futures\thread.py", line 92, in _worker
    work_item.run()
    │         └ <function _WorkItem.run at 0x0000010F231AF2E0>
    └ <concurrent.futures.thread._WorkItem object at 0x0000010F2334F1D0>
  File "D:\Miniconda3\Lib\concurrent\futures\thread.py", line 58, in run
    result = self.fn(*self.args, **self.kwargs)
             │    │   │    │       │    └ {}
             │    │   │    │       └ <concurrent.futures.thread._WorkItem object at 0x0000010F2334F1D0>
             │    │   │    └ (<function _unary_response_in_pool at 0x0000010F2335A840>, <grpc._cython.cygrpc.RequestCallEvent object at 0x0000010F23357650...
             │    │   └ <concurrent.futures.thread._WorkItem object at 0x0000010F2334F1D0>
             │    └ <built-in method run of _contextvars.Context object at 0x0000010F21FA3680>
             └ <concurrent.futures.thread._WorkItem object at 0x0000010F2334F1D0>
  File "E:\workspace\Mall_srv\venv\Lib\site-packages\grpc\_server.py", line 793, in _unary_response_in_pool
    response, proceed = _call_behavior(
                        └ <function _call_behavior at 0x0000010F2335A3E0>
> File "E:\workspace\Mall_srv\venv\Lib\site-packages\grpc\_server.py", line 610, in _call_behavior
    response_or_iterator = behavior(argument, context)
                           │        │         └ <grpc._server._Context object at 0x0000010F2334F170>
                           │        └ userId: 1
                           │          
                           └ <bound method UserFavServicer.GetFavList of <userop_srv.handler.userfav.userfav.UserFavServicer object at 0x0000010F22E08E60>>

  File "E:\workspace\Mall_srv\userop_srv\handler\userfav\userfav.py", line 34, in GetFavList
    fav_rsp.id = fav.id
    │            │   └ <peewee.FieldAccessor object at 0x0000010F21F7FD10>
    │            └ <UserFav: (1, 421)>
    └

AttributeError: Protocol message UserFavResponse has no "id" field.
2024-11-04 18:15:18.903 | ERROR    | grpc._server:_call_behavior:610 - An error has been caught in function '_call_behavior', process 'MainProcess' (27116), thread 'ThreadPoolExecutor-0_0' (6872):
Traceback (most recent call last):

  File "D:\Miniconda3\Lib\threading.py", line 1030, in _bootstrap
    self._bootstrap_inner()
    │    └ <function Thread._bootstrap_inner at 0x0000010F1FC619E0>
    └ <Thread(ThreadPoolExecutor-0_0, started daemon 6872)>
  File "D:\Miniconda3\Lib\threading.py", line 1073, in _bootstrap_inner
    self.run()
    │    └ <function Thread.run at 0x0000010F1FC616C0>
    └ <Thread(ThreadPoolExecutor-0_0, started daemon 6872)>
  File "D:\Miniconda3\Lib\threading.py", line 1010, in run
    self._target(*self._args, **self._kwargs)
    │    │        │    │        │    └ {}
    │    │        │    │        └ <Thread(ThreadPoolExecutor-0_0, started daemon 6872)>
    │    │        │    └ (<weakref at 0x0000010F233707C0; to 'ThreadPoolExecutor' at 0x0000010F22D7B320>, <_queue.SimpleQueue object at 0x0000010F2318...
    │    │        └ <Thread(ThreadPoolExecutor-0_0, started daemon 6872)>
    │    └ <function _worker at 0x0000010F231AF1A0>
    └ <Thread(ThreadPoolExecutor-0_0, started daemon 6872)>
  File "D:\Miniconda3\Lib\concurrent\futures\thread.py", line 92, in _worker
    work_item.run()
    │         └ <function _WorkItem.run at 0x0000010F231AF2E0>
    └ <concurrent.futures.thread._WorkItem object at 0x0000010F2334EA20>
  File "D:\Miniconda3\Lib\concurrent\futures\thread.py", line 58, in run
    result = self.fn(*self.args, **self.kwargs)
             │    │   │    │       │    └ {}
             │    │   │    │       └ <concurrent.futures.thread._WorkItem object at 0x0000010F2334EA20>
             │    │   │    └ (<function _unary_response_in_pool at 0x0000010F2335A840>, <grpc._cython.cygrpc.RequestCallEvent object at 0x0000010F22A95350...
             │    │   └ <concurrent.futures.thread._WorkItem object at 0x0000010F2334EA20>
             │    └ <built-in method run of _contextvars.Context object at 0x0000010F231031C0>
             └ <concurrent.futures.thread._WorkItem object at 0x0000010F2334EA20>
  File "E:\workspace\Mall_srv\venv\Lib\site-packages\grpc\_server.py", line 793, in _unary_response_in_pool
    response, proceed = _call_behavior(
                        └ <function _call_behavior at 0x0000010F2335A3E0>
> File "E:\workspace\Mall_srv\venv\Lib\site-packages\grpc\_server.py", line 610, in _call_behavior
    response_or_iterator = behavior(argument, context)
                           │        │         └ <grpc._server._Context object at 0x0000010F2334F2F0>
                           │        └ userId: 1
                           │          
                           └ <bound method UserFavServicer.GetFavList of <userop_srv.handler.userfav.userfav.UserFavServicer object at 0x0000010F22E08E60>>

  File "E:\workspace\Mall_srv\userop_srv\handler\userfav\userfav.py", line 34, in GetFavList
    fav_rsp.id = fav.id
    │            │   └ <peewee.FieldAccessor object at 0x0000010F21F7FD10>
    │            └ <UserFav: (1, 421)>
    └

AttributeError: Protocol message UserFavResponse has no "id" field.
2024-11-04 18:15:56.021 | INFO     | __main__:on_exit:27 - 注销<frame at 0x0000010F2334B4C0, file 'D:\\Miniconda3\\Lib\\threading.py', line 359, code wait>服务
2024-11-04 18:15:56.026 | ERROR    | common.register.consul:unregister:75 - 注销失败:404
2024-11-04 18:15:56.026 | INFO     | __main__:on_exit:29 - 注销成功
